Workbook

Sheet README
C1: 注意这个文档不能 merge！！ 发现冲突以后，先备份自己的改动，然后更新到最新版，然后再添加新的数据。
C3: 正式的数据从第二个 sheet 页开始,每页 从 D7 单元格开始有效 同一个表的数据要连续,中间不能有空行 Sheet 页的名字不要包含空格,中文等 | E3: 颜色示例(非必须,非强制)
C4: 请给特殊单元格,列名添加颜色,提高数据可读性 | E4: *自动生成 | F4: #唯一性检查 | G4: 公式=外键引用
C5: 理论上,表的前后顺序,sheet 页的顺序没有严格要求,但请尽量按照先插 后引用的顺序排列,减少迭代次数!
C7: 列名格式举例 | D7: 说明 | E7: 备注
C8: ROLE_CODE | D8: 普通
C9: *USER_ID | D9: *前置, 该列的值自动生成,当数据库存在等价记录时,这个值会被替换为数据库中已存在的值 | E9: 自增长(或序列)主键列. 当不作为外键引用时,一般写* 作为外键时,写可读的值 | F9: 目前 oracle 是序列,其他自增涨
C10: #USER_NAME | D10: #前置,表中所有带有#的列组成一个唯一性校验,在执行插入之前,会首先按照唯一键来检查数据库是否存在等价记录 | E10: 可以有多列.仅支持数字,字符串 当#列涉及到公式时,会先确定公式的值
C11: UNIT_PRICE(DECIMAL) | D11: (TYPE)指定这一列的类型,默认会自动检测: _ID结尾为数字; _DATE 结尾为日期; 其他默认为VARCHAR | E11: 一般不需要指定. 日期格式仅支持: yyyy-MM-dd HH:mm:ss yyyy-MM-dd
C12: ROLE_NAME:zh_CN | D12: :LANG 指定语言环境 | E12: TL 表数据不需要专门写
C15: 外键引用(公式) | D15: 用于引用外键,也可用于普通值 目前不支持特别复杂的公式 | E15: 自动增长列,如果被公式引用,最好写一个人可以读懂的值,增强公式可读性
C18: 关于公式的说明
C19: 一般用于引用自动生成的外键.所有公式均为 Excel 支持的标准公式,但不支持特别复杂的计算公式,比如范围计算
C20: E9 | D20: 相对引用当前页 E9 单元格
C21: $E$9 | D21: 绝对引用当前页 E9 单元格
C22: RESOURCE!E23 | D22: 引用 RESOURCE 页的 E23 单元格(相对)
C23: RESOURCE!$E$23 | D23: 引用 RESOURCE 页的 E23 单元格(绝对)
C25: 关于相对引用 | D25: 举例:当 F10 单元格引用 A9 时 将 F10 的复制到 F11 单元格时, F11 引用的是 A10 将 F10 的复制到 G11 时, G11 实际引用的是 B10 以上情况适用于拖拽填充
C26: 关于绝对引用 | D26: 复制公式单元格时,保持公式不变
C27: 相对引用,绝对引用各有用途. 直接拖拽填充就可以避免大量重复工作

Sheet 值集数据
A1: 日期 | B1: 作者 | C1: 说明 | D1: 表
E4: *自动生成 | F4: #唯一性检查 | G4: 公式=外键引用
A7: 2020-07-06 | B7: hzero | C7: LOV表 | D7: hpfm_lov | E7: *lov_id | F7: #lov_code | G7: lov_type_code | H7: route_name | I7: lov_name:zh_CN | J7: lov_name:en_US | K7: description:zh_CN | L7: description:en_US | M7: #tenant_id | N7: parent_lov_code | O7: parent_tenant_id | P7: custom_sql | Q7: custom_url | R7: value_field | S7: display_field | T7: must_page_flag | U7: enabled_flag | V7: translation_sql | W7: encrypt_field | X7: public_flag
E8: hpfm_lov-8 | F8: HMSG | G8: IDP | I8: 消息 | J8: 消息 | M8: 0 | T8: 1 | U8: 1 | W8: 0 | X8: 0
E9: hpfm_lov-9 | F9: HMSG.CALL.SERVER_TYPE | G9: IDP | I9: 语音服务类型 | J9: 语音服务类型 | M9: 0 | T9: 1 | U9: 1 | X9: 0
E10: hpfm_lov-10 | F10: HMSG.DINGTALK.AUTH_TYPE | G10: IDP | I10: 钉钉授权类型 | J10: Dingtalk auth type | M10: 0 | T10: 1 | U10: 1 | X10: 0
E11: hpfm_lov-11 | F11: HMSG.EMAIL.FILTER_STRATEGY | G11: IDP | I11: 邮箱账户筛选策略 | J11: 邮箱账户筛选策略 | M11: 0 | T11: 1 | U11: 1 | X11: 0
E12: hpfm_lov-12 | F12: HMSG.EMAIL_PROTOCOL | G12: IDP | I12: 邮件协议 | J12: 邮件协议 | M12: 0 | T12: 1 | U12: 1 | X12: 0
E13: hpfm_lov-13 | F13: HMSG.MESSAGE_CATEGORY | G13: IDP | I13: 消息分类 | J13: 消息分类 | M13: 0 | T13: 1 | U13: 1 | X13: 0
E14: hpfm_lov-14 | F14: HMSG.MESSAGE_SUBCATEGORY | G14: IDP | I14: 消息子分类 | J14: 消息子分类 | M14: 0 | N14: HMSG.MESSAGE_CATEGORY | O14: 0 | T14: 1 | U14: 1 | X14: 0
E15: hpfm_lov-15 | F15: HMSG.MESSAGE_TEMPLATE | G15: SQL | H15: hmsg | I15: 消息模板 | J15: 消息模板 | M15: 0 | P15: SELECT template_id, template_code, template_name, concat(template_name, concat('(', concat(lang, ')'))) lang_name FROM hmsg_message_template WHERE enabled_flag = 1 AND tenant_id IN ( 0 <if test=""tenantId != null""> , #{tenantId} </if> ) <if test=""templateCode != null and templateCode != ''""> <bind name =""templateCode"" value = ""'%' + templateCode + '%'""/> AND template_code like #{templateCode} </if> <if test=""templateName != null and templateName != ''""> <bind name =""templateName"" value = ""'%' + templateName + '%'""/> AND template_name like #{templateName} </if> ORDER BY template_code | T15: 1 | U15: 1 | W15: templateId | X15: 0
E16: hpfm_lov-16 | F16: HMSG.MESSAGE_TYPE | G16: IDP | I16: 消息模板类型 | J16: 消息模板类型 | M16: 0 | T16: 1 | U16: 1 | X16: 0
E17: hpfm_lov-17 | F17: HMSG.NOTICE.NOTICE_CATEGORY | G17: IDP | I17: 公告类别 | J17: 公告类别 | K17: 公告类别 | L17: 公告类别 | M17: 0 | N17: HMSG.NOTICE.RECERVER_TYPE | O17: 0 | T17: 1 | U17: 1 | X17: 0
E18: hpfm_lov-18 | F18: HMSG.NOTICE.NOTICE_TYPE | G18: IDP | I18: 公告类型 | J18: 公告类型 | K18: 公告类型 | L18: 公告类型 | M18: 0 | T18: 1 | U18: 1 | X18: 0
E19: hpfm_lov-19 | F19: HMSG.NOTICE.NOTICE_TYPE.CH | G19: IDP | I19: 公告类型-子集 | J19: 公告类型-子集 | K19: 公告类型-子集 | L19: 公告类型-子集 | M19: 0 | N19: HMSG.NOTICE.NOTICE_TYPE | O19: 0 | T19: 1 | U19: 1 | X19: 0
E20: hpfm_lov-20 | F20: HMSG.NOTICE.RECEIVER_RECORD_TYPE | G20: IDP | I20: 接收记录类型 | J20: 接收记录类型 | K20: 接收记录类型 | L20: 接收记录类型 | M20: 0 | T20: 1 | U20: 1 | X20: 0
E21: hpfm_lov-21 | F21: HMSG.NOTICE.RECERVER_TYPE | G21: IDP | I21: 公告发布对象类别 | J21: 公告发布对象类别 | K21: 公告发布对象类别 | L21: 公告发布对象类别 | M21: 0 | T21: 1 | U21: 1 | X21: 0
E22: hpfm_lov-22 | F22: HMSG.NOTICE.STATUS | G22: IDP | I22: 公告状态 | J22: 公告状态 | K22: 公告状态 | L22: 公告状态 | M22: 0 | T22: 1 | U22: 1 | X22: 0
E23: hpfm_lov-23 | F23: HMSG.NOTICE_RECEIVER_UNIT | G23: URL | H23: hmsg | I23: 公告消息接收方关联组织 | J23: 公告消息接收方关联组织 | K23: 公告消息接收方关联组织 | L23: 公告消息接收方关联组织 | M23: 0 | Q23: /v1/{organizationId}/notices/receivers/units | T23: 1 | U23: 1 | X23: 0
E24: hpfm_lov-24 | F24: HMSG.RECEIVER | G24: SQL | H24: hmsg | I24: 接收组 | J24: 接收者类型 | M24: 0 | P24: SELECT hrt.receiver_type_id, hrt.type_code, hrt.type_name, hrt.tenant_id FROM hmsg_receiver_type hrt WHERE hrt.enabled_flag = 1 <if test="tenantId != null"> AND hrt.tenant_id = #{tenantId} </if> <if test='typeCode != null'> <bind name="typeCodeLike" value="'%' + typeCode + '%'" /> and hrt.type_code like #{typeCodeLike} </if> <if test='typeName != null'> <bind name="typeNameLike" value="'%' + typeName + '%'" /> and hrt.type_name like #{typeNameLike} </if> | T24: 1 | U24: 1 | W24: receiverTypeId | X24: 0
E25: hpfm_lov-25 | F25: HMSG.RECEIVER.TYPE_MODE | G25: IDP | I25: 接收组模式 | J25: 接收组模式 | K25: 接收组模式 | L25: 接收组模式 | M25: 0 | T25: 1 | U25: 1 | X25: 1
E26: hpfm_lov-26 | F26: HMSG.RECEIVER_TYPE | G26: URL | H26: hmsg | I26: 接收组类型 | J26: 接收者类型 | M26: 0 | Q26: /v1/{organizationId}/receiver-types | T26: 1 | U26: 1 | X26: 0
E27: hpfm_lov-27 | F27: HMSG.SERVER | G27: SQL | H27: hmsg | I27: 消息服务 | J27: 消息服务 | K27: 消息服务 | L27: 消息服务 | M27: 0 | P27: select server_id, server_code, server_name <if test="typeCode == 'SMS'"> from hmsg_sms_server </if> <if test="typeCode == 'EMAIL'"> from hmsg_email_server </if> <if test="typeCode == 'WC_O'"> from hmsg_wechat_official </if> <if test="typeCode == 'WC_E'"> from hmsg_wechat_enterprise </if> <if test="typeCode == 'DT'"> from hmsg_dingtalk_server </if> <if test="typeCode == 'CALL'"> from hmsg_call_server </if> <if test="typeCode == 'WEB_HOOK'"> from hmsg_webhook_server </if> where enabled_flag = 1 and tenant_id in (0,#{tenantId}) <if test="serverCode != null and serverCode != ''"> <bind name="serverCode" value="'%' + serverCode + '%'"/> and server_code like #{serverCode} </if> <if test="serverName != null and serverName != ''"> <bind name="serverName" value="'%' + serverName + '%'"/> and server_name like #{serverName} </if> | T27: 1 | U27: 1 | X27: 0
E28: hpfm_lov-28 | F28: HMSG.SERVER_WEBHOOK | G28: SQL | H28: hmsg | I28: 查询WebHook | J28: 查询WebHook | M28: 0 | P28: <bind name="lang" value="@io.choerodon.mybatis.helper.LanguageHelper@language()"/> SELECT hws.server_code, hws.tenant_id, hws.server_name, hlvt.meaning server_type_meaning FROM hmsg_webhook_server hws JOIN hpfm_lov_value hlv ON hlv.lov_code='HMSG.WEBHOOK_TYPE' AND hws.server_type = hlv.value JOIN hpfm_lov_value_tl hlvt ON hlv.lov_value_id = hlvt.lov_value_id AND hlvt.lang = #{lang} WHERE hws.tenant_id = 0 <if test="tenantId != null and tenantId != 0"> OR hws.tenant_id = #{tenantId} AND hws.server_id NOT IN ( SELECT hws1.server_id FROM hmsg_webhook_server hws1 WHERE hws1.tenant_id = #{tenantId} AND EXISTS ( SELECT 1 FROM hmsg_webhook_server hws2 WHERE hws2.server_code = hws1.server_code AND hws2.tenant_id = #{tenantId} ) ) </if> AND NOT EXISTS ( SELECT 1 FROM hmsg_template_server_wh htsw WHERE htsw.server_code = hws.server_code AND htsw.tenant_id = hws.tenant_id AND htsw.temp_server_line_id = #{tempServerLineId} ) <if test="serverCode != null and serverCode != ''"> <bind name="serverCodeLike" value="'%'+serverCode+'%'"/> AND hws.server_code LIKE #{serverCodeLike} </if> <if test="serverName != null and serverName != ''"> <bind name="serverNameLike" value="'%'+serverName+'%'"/> AND hws.server_name LIKE #{serverNameLike} </if> | T28: 1 | U28: 1 | X28: 0
E29: hpfm_lov-29 | F29: HMSG.SITE.NOTICE_RECEIVER_UNIT | G29: URL | H29: hmsg | I29: 公告发布接收方关联组织 | J29: 公告发布接收方关联组织 | M29: 0 | Q29: /v1/notices/receivers/units | T29: 1 | U29: 1 | X29: 0
E30: hpfm_lov-30 | F30: HMSG.SITE.USER | G30: SQL | H30: iam | I30: 消息服务选择用户 | J30: Message service selection user | M30: 0 | P30: SELECT iu.id, iu.login_name, iu.email, iu.real_name, CONCAT(iu.real_name,CONCAT(CONCAT('(',iu.login_name),')')) splice_name, iu.phone FROM iam_user iu WHERE iu.id > 0 <if test="organizationId != null"> AND iu.organization_id = #{organizationId} </if> and iu.is_enabled = 1 and iu.is_locked = 0 <if test="loginName != null and loginName != ''"> <bind name="loginNameLike" value="'%'+loginName+'%'" /> AND iu.login_name LIKE #{loginNameLike} </if> <if test="realName != null and realName != ''"> <bind name="realNameLike" value="'%'+realName+'%'" /> AND iu.real_name LIKE #{realNameLike} </if> <if test="phone != null and phone != ''"> <bind name="phoneLike" value="'%'+phone+'%'" /> AND iu.phone LIKE #{phoneLike} </if> <if test="email != null and email != ''"> <bind name="emailLike" value="'%'+email+'%'" /> AND iu.email LIKE #{emailLike} </if> ORDER BY iu.id | T30: 1 | U30: 1 | X30: 0
E31: hpfm_lov-31 | F31: HMSG.SMS_SERVER_TYPE | G31: IDP | I31: 短信服务类型 | J31: 短信服务类型 | M31: 0 | T31: 1 | U31: 1 | X31: 0
E32: hpfm_lov-32 | F32: HMSG.TEMPLATE_SERVER | G32: SQL | H32: hmsg | I32: 消息模板账户 | J32: 消息模板账户 | K32: 创建消息事件选择消息模板账户 | L32: 创建消息事件选择消息模板账户 | M32: 0 | P32: SELECT hts.temp_server_id, hts.message_code, hts.message_name, hts.tenant_id FROM hmsg_template_server hts WHERE hts.enabled_flag = 1 <if test="tenantId != null"> AND hts.tenant_id = #{tenantId} </if> <if test="messageCode != null and messageCode != ''"> <bind name="messageCodeLike" value="'%' + messageCode + '%'"/> AND hts.message_code LIKE #{messageCodeLike} </if> <if test="messageName != null and messageName != ''"> <bind name="messageNameLike" value="'%' + messageName + '%'"/> AND hts.message_name LIKE #{messageNameLike} </if> | T32: 1 | U32: 1 | W32: tempServerId | X32: 0
E33: hpfm_lov-33 | F33: HMSG.TEMPLATE_SERVER.TEMPLATE | G33: SQL | H33: hmsg | I33: 关系维护模板 | J33: 关系维护模板 | K33: 邮件发送关系维护值集 | L33: 邮件发送关系维护值集 | M33: 0 | P33: SELECT hmt.template_id, hmt.template_code, hmt.template_name FROM hmsg_message_template hmt WHERE 1=1 <if test="templateCode!= null and templateCode!= ''"> <bind name="templateCode" value="'%' + templateCode+ '%'"/> and hmt.template_code like #{templateCode} </if> <if test="templateName!= null and templateName!= ''"> <bind name="templateName" value="'%' + templateName+ '%'"/> and hmt.template_name like #{templateName} </if> <if test="tenantId != null and tenantId != ''"> and hmt.tenant_id = #{tenantId} </if> <if test="templateId != null and templateId != ''"> and hmt.template_id = #{templateId} </if> | T33: 1 | U33: 1 | X33: 0
E34: hpfm_lov-34 | F34: HMSG.TEMP_SERVER.CATEGORY | G34: IDP | I34: 消息发送配置分类 | J34: 消息发送配置分类 | K34: 值只能使用大写 | L34: ddeb | M34: 0 | T34: 1 | U34: 1 | X34: 0
E35: hpfm_lov-35 | F35: HMSG.TEMP_SERVER.SUBCATEGORY | G35: IDP | I35: 消息发送配置子类型 | J35: 消息发送配置子类型 | K35: 值只能使用大写 | M35: 0 | N35: HMSG.TEMP_SERVER.CATEGORY | O35: 0 | T35: 1 | U35: 1 | X35: 0
E36: hpfm_lov-36 | F36: HMSG.TRANSACTION_STATUS | G36: IDP | I36: 消息事务状态 | J36: 消息事务状态 | M36: 0 | T36: 1 | U36: 1 | X36: 0
E37: hpfm_lov-37 | F37: HMSG.USER.MESSAGE_TYPE | G37: IDP | I37: 用户消息类型 | J37: 用户消息类型 | K37: 用户消息类型 | L37: 用户消息类型 | M37: 0 | T37: 1 | U37: 1 | X37: 0
E38: hpfm_lov-38 | F38: HMSG.WEBHOOK_TYPE | G38: IDP | I38: WEBHOOK类型 | J38: WEBHOOK类型 | M38: 0 | T38: 1 | U38: 1 | X38: 0
E39: hpfm_lov-39 | F39: HMSG.WECHAT.AUTH_TYPE | G39: IDP | I39: 微信授权类型 | J39: 微信授权类型 | M39: 0 | T39: 1 | U39: 1 | X39: 0
A41: 2020-07-06 | B41: hzero | C41: LOV独立值集表 | D41: hpfm_lov_value | E41: *lov_value_id | F41: #lov_id | G41: lov_code | H41: #value | I41: meaning:zh_CN | J41: meaning:en_US | K41: description:zh_CN | L41: description:en_US | M41: #tenant_id | N41: tag | O41: order_seq | P41: #parent_value | Q41: start_date_active(DATE) | R41: end_date_active(DATE) | S41: enabled_flag
E42: * | F42: =值集数据!$E$8 -> hpfm_lov-8 | G42: HMSG | H42: SITE | I42: site层级 | J42: site层级 | M42: 0 | O42: 1 | S42: 1
E43: * | F43: =值集数据!$E$8 -> hpfm_lov-8 | G43: HMSG | H43: PROJECT | I43: project层级 | J43: project层级 | M43: 0 | O43: 1 | S43: 1
E44: * | F44: =值集数据!$E$8 -> hpfm_lov-8 | G44: HMSG | H44: ORGANIZATION | I44: 组织层级 | J44: 组织层级 | M44: 0 | O44: 1 | S44: 1
E45: * | F45: =值集数据!$E$9 -> hpfm_lov-9 | G45: HMSG.CALL.SERVER_TYPE | H45: JINGDONG | I45: 京东云 | J45: 京东云 | K45: 标记为表单配置编码 | M45: 0 | N45: HMSG.CALL.JINGDONG | O45: 10 | S45: 1
...
