Workbook

Sheet README
C1: 注意这个文档不能 merge！！ 发现冲突以后，先备份自己的改动，然后更新到最新版，然后再添加新的数据。
C3: 正式的数据从第二个 sheet 页开始,每页 从 D7 单元格开始有效 同一个表的数据要连续,中间不能有空行 Sheet 页的名字不要包含空格,中文等 | E3: 颜色示例(非必须,非强制)
C4: 请给特殊单元格,列名添加颜色,提高数据可读性 | E4: *自动生成 | F4: #唯一性检查 | G4: 公式=外键引用
C5: 理论上,表的前后顺序,sheet 页的顺序没有严格要求,但请尽量按照先插 后引用的顺序排列,减少迭代次数!
C7: 列名格式举例 | D7: 说明 | E7: 备注
C8: ROLE_CODE | D8: 普通
C9: *USER_ID | D9: *前置, 该列的值自动生成,当数据库存在等价记录时,这个值会被替换为数据库中已存在的值 | E9: 自增长(或序列)主键列. 当不作为外键引用时,一般写* 作为外键时,写可读的值 | F9: 目前 oracle 是序列,其他自增涨
C10: #USER_NAME | D10: #前置,表中所有带有#的列组成一个唯一性校验,在执行插入之前,会首先按照唯一键来检查数据库是否存在等价记录 | E10: 可以有多列.仅支持数字,字符串 当#列涉及到公式时,会先确定公式的值
C11: UNIT_PRICE(DECIMAL) | D11: (TYPE)指定这一列的类型,默认会自动检测: _ID结尾为数字; _DATE 结尾为日期; 其他默认为VARCHAR | E11: 一般不需要指定. 日期格式仅支持: yyyy-MM-dd HH:mm:ss yyyy-MM-dd
C12: ROLE_NAME:zh_CN | D12: :LANG 指定语言环境 | E12: TL 表数据不需要专门写
C15: 外键引用(公式) | D15: 用于引用外键,也可用于普通值 目前不支持特别复杂的公式 | E15: 自动增长列,如果被公式引用,最好写一个人可以读懂的值,增强公式可读性
C18: 关于公式的说明
C19: 一般用于引用自动生成的外键.所有公式均为 Excel 支持的标准公式,但不支持特别复杂的计算公式,比如范围计算
C20: E9 | D20: 相对引用当前页 E9 单元格
C21: $E$9 | D21: 绝对引用当前页 E9 单元格
C22: RESOURCE!E23 | D22: 引用 RESOURCE 页的 E23 单元格(相对)
C23: RESOURCE!$E$23 | D23: 引用 RESOURCE 页的 E23 单元格(绝对)
C25: 关于相对引用 | D25: 举例:当 F10 单元格引用 A9 时 将 F10 的复制到 F11 单元格时, F11 引用的是 A10 将 F10 的复制到 G11 时, G11 实际引用的是 B10 以上情况适用于拖拽填充
C26: 关于绝对引用 | D26: 复制公式单元格时,保持公式不变
C27: 相对引用,绝对引用各有用途. 直接拖拽填充就可以避免大量重复工作

Sheet 菜单SAAS版
A1: 日期 | B1: 作者 | C1: 说明 | D1: 表
E4: *自动生成 | F4: #唯一性检查 | G4: 公式=外键引用
A7: 2020-07-09 | B7: hzero | C7: 菜单-saas | D7: iam_menu | E7: *id | F7: #code | G7: name:zh_CN | H7: name:en_US | I7: h_quick_index | J7: #fd_level | K7: parent_id | L7: type | M7: sort | N7: is_default | O7: icon | P7: route | Q7: h_custom_flag | R7: #h_tenant_id | S7: h_level_path | T7: h_virtual_flag | U7: h_controller_type | V7: h_permission_type | W7: h_description | X7: h_enabled_flag | Y7: category
E8: iam_menu-8 | F8: hzero.site.config | G8: 平台治理 | H8: Platform governance | I8: PTZL | J8: site | K8: 0 | L8: root | M8: 150 | N8: 1 | O8: service-governance | Q8: 0 | R8: 0 | S8: hzero.site.config | T8: 0 | V8: api | X8: 1
E9: iam_menu-9 | F9: hzero.site.config.platform-manager | G9: 服务监控 | H9: Service Monitor | J9: site | K9: =菜单SAAS版!$E$8 -> iam_menu-8 | L9: dir | M9: 40 | N9: 1 | O9: system-management | Q9: 0 | R9: 0 | S9: hzero.site.config|hzero.site.config.platform-manager | T9: 0 | V9: api | X9: 1
E10: iam_menu-10 | F10: hzero.site.config.inner.admin.console | G10: 服务监控控制台 | H10: 服务监控控制台 | I10: FWJKKZT | J10: site | K10: =菜单SAAS版!$E$9 -> iam_menu-9 | L10: inner-link | M10: 10 | N10: 1 | O10: dispatch-platform | P10: /hadm | Q10: 0 | R10: 0 | S10: hzero.site.config|hzero.site.config.platform-manager|hzero.site.config.inner.admin.console | T10: 0 | V10: api | W10: Spring Boot Admin 2.0.6 | X10: 1
E11: iam_menu-11 | F11: hzero.site.config.inner.admin.console.ps.default | G11: 默认权限集 | H11: Default permission set | J11: site | K11: =菜单SAAS版!$E$10 -> iam_menu-10 | L11: ps | N11: 1 | O11: link | Q11: 0 | R11: 0 | S11: hzero.site.config|hzero.site.config.platform-manager|hzero.site.config.inner.admin.console|hzero.site.config.inner.admin.console.ps.default | T11: 0 | V11: api | X11: 1
E12: iam_menu-12 | F12: hzero.site.config.platform-manager.api-overview | G12: API统计 | H12: API统计 | I12: APITJ | J12: site | K12: =菜单SAAS版!$E$9 -> iam_menu-9 | L12: menu | M12: 30 | N12: 1 | O12: scheduling-service | P12: /hadm/api-overview | Q12: 0 | R12: 0 | S12: hzero.site.config|hzero.site.config.platform-manager|hzero.site.config.platform-manager.api-overview | T12: 0 | V12: api | X12: 1
E13: iam_menu-13 | F13: hzero.site.config.platform-manager.api-overview.ps.default | G13: 默认权限集 | H13: 默认权限集 | J13: site | K13: =菜单SAAS版!$E$12 -> iam_menu-12 | L13: ps | M13: 10 | N13: 1 | Q13: 0 | R13: 0 | S13: hzero.site.config|hzero.site.config.platform-manager|hzero.site.config.platform-manager.api-overview|hzero.site.config.platform-manager.api-overview.ps.default | T13: 0 | U13: disabled | V13: api | X13: 1
E14: iam_menu-14 | F14: hzero.site.config.platform-manager.api-test | G14: API测试 | H14: API Test | I14: ACS | J14: site | K14: =菜单SAAS版!$E$9 -> iam_menu-9 | L14: menu | M14: 40 | N14: 1 | O14: yunyingguanli | P14: /hadm/api-test | Q14: 0 | R14: 0 | S14: hzero.site.config|hzero.site.config.platform-manager|hzero.site.config.platform-manager.api-test | T14: 0 | V14: api | X14: 1
E15: iam_menu-15 | F15: hzero.site.config.platform-manager.api-test.ps.default | G15: 默认权限集 | H15: 默认权限集 | J15: site | K15: =菜单SAAS版!$E$14 -> iam_menu-14 | L15: ps | M15: 10 | N15: 1 | Q15: 0 | R15: 0 | S15: hzero.site.config|hzero.site.config.platform-manager|hzero.site.config.platform-manager.api-test|hzero.site.config.platform-manager.api-test.ps.default | T15: 0 | U15: disabled | V15: api | X15: 1
E16: iam_menu-16 | F16: hzero.site.config.platform-manager.instance | G16: 微服务实例 | H16: Micro Instance | I16: WFWSL | J16: site | K16: =菜单SAAS版!$E$9 -> iam_menu-9 | L16: menu | M16: 20 | N16: 1 | O16: development-management | P16: /hadm/instance | Q16: 0 | R16: 0 | S16: hzero.site.config|hzero.site.config.platform-manager|hzero.site.config.platform-manager.instance | T16: 0 | V16: api | X16: 1
E17: iam_menu-17 | F17: hzero.site.config.platform-manager.instance.ps.default | G17: 默认权限集 | H17: 默认权限集 | J17: site | K17: =菜单SAAS版!$E$16 -> iam_menu-16 | L17: ps | M17: 10 | N17: 1 | Q17: 0 | R17: 0 | S17: hzero.site.config|hzero.site.config.platform-manager|hzero.site.config.platform-manager.instance|hzero.site.config.platform-manager.instance.ps.default | T17: 0 | U17: disabled | V17: api | X17: 1
E18: iam_menu-18 | F18: hzero.site.config.service-config | G18: 服务配置 | H18: Service Config | I18: FWPZ | J18: site | K18: =菜单SAAS版!$E$8 -> iam_menu-8 | L18: menu | M18: 20 | N18: 1 | O18: workflow-setting | P18: /hadm/config | Q18: 0 | R18: 0 | S18: hzero.site.config|hzero.site.config.service-config | T18: 0 | V18: api | X18: 1
E19: iam_menu-19 | F19: hzero.site.config.service-config.ps.create | G19: 服务配置-创建集 | H19: 服务配置-创建集 | J19: site | K19: =菜单SAAS版!$E$18 -> iam_menu-18 | L19: ps | M19: 10 | N19: 1 | Q19: 0 | R19: 0 | S19: hzero.site.config|hzero.site.config.service-config|hzero.site.config.service-config.ps.create | T19: 0 | V19: api | X19: 1
E20: iam_menu-20 | F20: hzero.site.config.service-config.ps.default | G20: 服务配置默认权限集 | H20: 服务配置默认权限集 | J20: site | K20: =菜单SAAS版!$E$18 -> iam_menu-18 | L20: ps | M20: 0 | N20: 1 | Q20: 0 | R20: 0 | S20: hzero.site.config|hzero.site.config.service-config|hzero.site.config.service-config.ps.default | T20: 0 | V20: api | X20: 1
E21: iam_menu-21 | F21: hzero.site.config.service-config.ps.delete | G21: 服务配置-删除集 | H21: 服务配置-删除集 | J21: site | K21: =菜单SAAS版!$E$18 -> iam_menu-18 | L21: ps | M21: 10 | N21: 1 | Q21: 0 | R21: 0 | S21: hzero.site.config|hzero.site.config.service-config|hzero.site.config.service-config.ps.delete | T21: 0 | V21: api | X21: 1
E22: iam_menu-22 | F22: hzero.site.config.service-config.ps.query | G22: 服务配置-查询集 | H22: 服务配置-查询集 | J22: site | K22: =菜单SAAS版!$E$18 -> iam_menu-18 | L22: ps | M22: 10 | N22: 1 | Q22: 0 | R22: 0 | S22: hzero.site.config|hzero.site.config.service-config|hzero.site.config.service-config.ps.query | T22: 0 | V22: api | X22: 1
E23: iam_menu-23 | F23: hzero.site.config.service-manage | G23: 服务管理 | H23: Service management | I23: FWGL | J23: site | K23: =菜单SAAS版!$E$8 -> iam_menu-8 | L23: menu | M23: 10 | N23: 1 | O23: service-governance | P23: /hadm/service | Q23: 0 | R23: 0 | S23: hzero.site.config|hzero.site.config.service-manage | T23: 0 | V23: api | X23: 1
E24: iam_menu-24 | F24: hzero.site.config.service-manage.ps.create | G24: 服务管理-创建集 | H24: 服务管理-创建集 | J24: site | K24: =菜单SAAS版!$E$23 -> iam_menu-23 | L24: ps | M24: 10 | N24: 1 | Q24: 0 | R24: 0 | S24: hzero.site.config|hzero.site.config.service-manage|hzero.site.config.service-manage.ps.create | T24: 0 | V24: api | X24: 1
E25: iam_menu-25 | F25: hzero.site.config.service-manage.ps.default | G25: 服务管理默认权限集 | H25: 服务管理默认权限集 | J25: site | K25: =菜单SAAS版!$E$23 -> iam_menu-23 | L25: ps | M25: 0 | N25: 1 | Q25: 0 | R25: 0 | S25: hzero.site.config|hzero.site.config.service-manage|hzero.site.config.service-manage.ps.default | T25: 0 | V25: api | X25: 1
E26: iam_menu-26 | F26: hzero.site.config.service-manage.ps.delete | G26: 服务管理-删除集 | H26: 服务管理-删除集 | J26: site | K26: =菜单SAAS版!$E$23 -> iam_menu-23 | L26: ps | M26: 10 | N26: 1 | Q26: 0 | R26: 0 | S26: hzero.site.config|hzero.site.config.service-manage|hzero.site.config.service-manage.ps.delete | T26: 0 | V26: api | X26: 1
E27: iam_menu-27 | F27: hzero.site.config.service-manage.ps.query | G27: 服务管理-查询集 | H27: 服务管理-查询集 | J27: site | K27: =菜单SAAS版!$E$23 -> iam_menu-23 | L27: ps | M27: 10 | N27: 1 | Q27: 0 | R27: 0 | S27: hzero.site.config|hzero.site.config.service-manage|hzero.site.config.service-manage.ps.query | T27: 0 | V27: api | X27: 1
E28: iam_menu-28 | F28: hzero.site.config.sharding | G28: Sharding配置管理 | H28: sharding配置管理 | J28: site | K28: =菜单SAAS版!$E$8 -> iam_menu-8 | L28: dir | M28: 50 | N28: 1 | O28: map | Q28: 0 | R28: 0 | S28: hzero.site.config|hzero.site.config.sharding | T28: 0 | V28: api | X28: 1
E29: iam_menu-29 | F29: hzero.site.config.svc-governance | G29: 服务治理 | H29: Service Governance | J29: site | K29: =菜单SAAS版!$E$8 -> iam_menu-8 | L29: dir | M29: 30 | N29: 1 | O29: basic-data-management | Q29: 0 | R29: 0 | S29: hzero.site.config|hzero.site.config.svc-governance | T29: 0 | V29: api | X29: 1
E30: iam_menu-30 | F30: hzero.site.config.api-limit | G30: API访问控制 | H30: API管控 | I30: APIGK | J30: site | K30: =菜单SAAS版!$E$29 -> iam_menu-29 | L30: menu | M30: 30 | N30: 1 | O30: workflow-setting | P30: /hadm/api-limit | Q30: 0 | R30: 0 | S30: hzero.site.config|hzero.site.config.svc-governance|hzero.site.config.api-limit | T30: 0 | V30: api | X30: 1
E31: iam_menu-31 | F31: hzero.site.config.api-limit.hadm.api-limit.detail.-monitorRuleId.button.addBlack | G31: API访问控制-加入黑名单 | H31: API访问控制-加入黑名单 | J31: site | K31: =菜单SAAS版!$E$30 -> iam_menu-30 | L31: ps | M31: 0 | N31: 1 | Q31: 0 | R31: 0 | S31: hzero.site.config|hzero.site.config.svc-governance|hzero.site.config.api-limit|hzero.site.config.api-limit.hadm.api-limit.detail.-monitorRuleId.button.addBlack | T31: 0 | V31: button | X31: 1
E32: iam_menu-32 | F32: hzero.site.config.api-limit.hadm.api-limit.list.button.apply | G32: API访问控制-应用 | H32: API访问控制-应用 | J32: site | K32: =菜单SAAS版!$E$30 -> iam_menu-30 | L32: ps | M32: 0 | N32: 1 | Q32: 0 | R32: 0 | S32: hzero.site.config|hzero.site.config.svc-governance|hzero.site.config.api-limit|hzero.site.config.api-limit.hadm.api-limit.list.button.apply | T32: 0 | V32: button | X32: 1
E33: iam_menu-33 | F33: hzero.site.config.api-limit.hadm.api-limit.list.button.create | G33: API访问控制-新建 | H33: API访问控制-新建 | J33: site | K33: =菜单SAAS版!$E$30 -> iam_menu-30 | L33: ps | M33: 0 | N33: 1 | Q33: 0 | R33: 0 | S33: hzero.site.config|hzero.site.config.svc-governance|hzero.site.config.api-limit|hzero.site.config.api-limit.hadm.api-limit.list.button.create | T33: 0 | V33: button | X33: 1
E34: iam_menu-34 | F34: hzero.site.config.api-limit.hadm.api-limit.list.button.delete | G34: API访问控制-删除 | H34: API访问控制-删除 | J34: site | K34: =菜单SAAS版!$E$30 -> iam_menu-30 | L34: ps | M34: 0 | N34: 1 | Q34: 0 | R34: 0 | S34: hzero.site.config|hzero.site.config.svc-governance|hzero.site.config.api-limit|hzero.site.config.api-limit.hadm.api-limit.list.button.delete | T34: 0 | V34: button | X34: 1
E35: iam_menu-35 | F35: hzero.site.config.api-limit.hadm.api-limit.list.button.flowControl | G35: API访问控制-流量控制 | H35: API访问控制-流量控制 | J35: site | K35: =菜单SAAS版!$E$30 -> iam_menu-30 | L35: ps | M35: 0 | N35: 1 | Q35: 0 | R35: 0 | S35: hzero.site.config|hzero.site.config.svc-governance|hzero.site.config.api-limit|hzero.site.config.api-limit.hadm.api-limit.list.button.flowControl | T35: 0 | V35: button | X35: 1
E36: iam_menu-36 | F36: hzero.site.config.api-limit.ps.default | G36: 默认权限集 | H36: 默认权限集 | J36: site | K36: =菜单SAAS版!$E$30 -> iam_menu-30 | L36: ps | M36: 10 | N36: 1 | Q36: 0 | R36: 0 | S36: hzero.site.config|hzero.site.config.svc-governance|hzero.site.config.api-limit|hzero.site.config.api-limit.ps.default | T36: 0 | U36: disabled | V36: api | X36: 1
E37: iam_menu-37 | F37: hzero.site.config.hzero.zuul-limit | G37: 限流规则 | H37: Zuul Limit | I37: XLGZ | J37: site | K37: =菜单SAAS版!$E$29 -> iam_menu-29 | L37: menu | M37: 10 | N37: 1 | O37: basic-data-management | P37: /hadm/rate-limit | Q37: 0 | R37: 0 | S37: hzero.site.config|hzero.site.config.svc-governance|hzero.site.config.hzero.zuul-limit | T37: 0 | V37: api | X37: 1
E38: iam_menu-38 | F38: hzero.site.config.hzero.zuul-limit.hadm.rate-limit.detail.-rateLimitId.button.delete | G38: 限流规则-维度-删除限流规则(表格) | H38: 限流规则-维度-删除限流规则(表格) | J38: site | K38: =菜单SAAS版!$E$37 -> iam_menu-37 | L38: ps | M38: 0 | N38: 1 | O38: basic-data-management | Q38: 0 | R38: 0 | S38: hzero.site.config|hzero.site.config.svc-governance|hzero.site.config.hzero.zuul-limit|hzero.site.config.hzero.zuul-limit.hadm.rate-limit.detail.-rateLimitId.button.delete | T38: 0 | V38: button | X38: 1
E39: iam_menu-39 | F39: hzero.site.config.hzero.zuul-limit.hadm.rate-limit.detail.-rateLimitId.button.edit | G39: 限流规则-维度-编辑限流规则(表格) | H39: 限流规则-维度-编辑限流规则(表格) | J39: site | K39: =菜单SAAS版!$E$37 -> iam_menu-37 | L39: ps | M39: 0 | N39: 1 | O39: basic-data-management | Q39: 0 | R39: 0 | S39: hzero.site.config|hzero.site.config.svc-governance|hzero.site.config.hzero.zuul-limit|hzero.site.config.hzero.zuul-limit.hadm.rate-limit.detail.-rateLimitId.button.edit | T39: 0 | V39: button | X39: 1
E40: iam_menu-40 | F40: hzero.site.config.hzero.zuul-limit.hadm.rate-limit.detail.-rateLimitId.button.valueAdd | G40: 限流规则-维度-新增限流规则 | H40: 限流规则-维度-新增限流规则 | J40: site | K40: =菜单SAAS版!$E$37 -> iam_menu-37 | L40: ps | M40: 0 | N40: 1 | O40: basic-data-management | Q40: 0 | R40: 0 | S40: hzero.site.config|hzero.site.config.svc-governance|hzero.site.config.hzero.zuul-limit|hzero.site.config.hzero.zuul-limit.hadm.rate-limit.detail.-rateLimitId.button.valueAdd | T40: 0 | V40: button | X40: 1
E41: iam_menu-41 | F41: hzero.site.config.hzero.zuul-limit.ps.create | G41: 限流规则-创建集 | H41: 限流规则-创建集 | J41: site | K41: =菜单SAAS版!$E$37 -> iam_menu-37 | L41: ps | M41: 10 | N41: 1 | Q41: 0 | R41: 0 | S41: hzero.site.config|hzero.site.config.svc-governance|hzero.site.config.hzero.zuul-limit|hzero.site.config.hzero.zuul-limit.ps.create | T41: 0 | V41: api | X41: 1
E42: iam_menu-42 | F42: hzero.site.config.hzero.zuul-limit.ps.default | G42: 限流规则默认权限集 | H42: 限流规则默认权限集 | I42: XLGZMRQXJ | J42: site | K42: =菜单SAAS版!$E$37 -> iam_menu-37 | L42: ps | M42: 0 | N42: 1 | O42: link | Q42: 0 | R42: 0 | S42: hzero.site.config|hzero.site.config.svc-governance|hzero.site.config.hzero.zuul-limit|hzero.site.config.hzero.zuul-limit.ps.default | T42: 0 | V42: api | X42: 1
E43: iam_menu-43 | F43: hzero.site.config.hzero.zuul-limit.ps.delete | G43: 限流规则-删除集 | H43: 限流规则-删除集 | J43: site | K43: =菜单SAAS版!$E$37 -> iam_menu-37 | L43: ps | M43: 10 | N43: 1 | Q43: 0 | R43: 0 | S43: hzero.site.config|hzero.site.config.svc-governance|hzero.site.config.hzero.zuul-limit|hzero.site.config.hzero.zuul-limit.ps.delete | T43: 0 | V43: api | X43: 1
E44: iam_menu-44 | F44: hzero.site.config.hzero.zuul-limit.ps.query | G44: 限流规则-查询集 | H44: 限流规则-查询集 | J44: site | K44: =菜单SAAS版!$E$37 -> iam_menu-37 | L44: ps | M44: 10 | N44: 1 | Q44: 0 | R44: 0 | S44: hzero.site.config|hzero.site.config.svc-governance|hzero.site.config.hzero.zuul-limit|hzero.site.config.hzero.zuul-limit.ps.query | T44: 0 | V44: api | X44: 1
...

Sheet 菜单权限
A1: 日期 | B1: 作者 | C1: 说明 | D1: 表
E4: *自动生成 | F4: #唯一性检查 | G4: 公式=外键引用
A7: 2020-07-09 | B7: hzero | C7: 菜单权限 | D7: iam_menu_permission | E7: *id | F7: #menu_id | G7: #permission_code
E8: iam_menu_permission-8 | F8: =菜单SAAS版!$E$36 -> iam_menu-36 | G8: hzero-admin.api-limit-site.createOrUpdate
E9: iam_menu_permission-9 | F9: =菜单SAAS版!$E$36 -> iam_menu-36 | G9: hzero-admin.api-limit-site.detail
E10: iam_menu_permission-10 | F10: =菜单SAAS版!$E$36 -> iam_menu-36 | G10: hzero-admin.api-monitor-rule-site.apply
E11: iam_menu_permission-11 | F11: =菜单SAAS版!$E$36 -> iam_menu-36 | G11: hzero-admin.api-monitor-rule-site.create
E12: iam_menu_permission-12 | F12: =菜单SAAS版!$E$36 -> iam_menu-36 | G12: hzero-admin.api-monitor-rule-site.delete
E13: iam_menu_permission-13 | F13: =菜单SAAS版!$E$36 -> iam_menu-36 | G13: hzero-admin.api-monitor-rule-site.page
E14: iam_menu_permission-14 | F14: =菜单SAAS版!$E$36 -> iam_menu-36 | G14: hzero-admin.api-monitor-site.blackList
E15: iam_menu_permission-15 | F15: =菜单SAAS版!$E$36 -> iam_menu-36 | G15: hzero-admin.api-monitor-site.page
E16: iam_menu_permission-16 | F16: =菜单SAAS版!$E$42 -> iam_menu-42 | G16: HADM.SERVICE
E17: iam_menu_permission-17 | F17: =菜单SAAS版!$E$42 -> iam_menu-42 | G17: HADM.SERVICE_CONFIG
E18: iam_menu_permission-18 | F18: =菜单SAAS版!$E$42 -> iam_menu-42 | G18: HADM.SERVICE_ROUTE
E19: iam_menu_permission-19 | F19: =菜单SAAS版!$E$42 -> iam_menu-42 | G19: HCNF.ZUUL.SERVICE_CONFIG
E20: iam_menu_permission-20 | F20: =菜单SAAS版!$E$42 -> iam_menu-42 | G20: HIAM.TENANT.USER
E21: iam_menu_permission-21 | F21: =菜单SAAS版!$E$42 -> iam_menu-42 | G21: HIAM.TENANT_ROLE
E22: iam_menu_permission-22 | F22: =菜单SAAS版!$E$42 -> iam_menu-42 | G22: HPFM.TENANT_PAGING
E23: iam_menu_permission-23 | F23: =菜单SAAS版!$E$42 -> iam_menu-42 | G23: LOV_ROLE
E24: iam_menu_permission-24 | F24: =菜单SAAS版!$E$42 -> iam_menu-42 | G24: LOV_TENANT
E25: iam_menu_permission-25 | F25: =菜单SAAS版!$E$42 -> iam_menu-42 | G25: LOV_USER
E26: iam_menu_permission-26 | F26: =菜单SAAS版!$E$42 -> iam_menu-42 | G26: hzero-admin.gateway-rate-limit-dimension-site-level.create
E27: iam_menu_permission-27 | F27: =菜单SAAS版!$E$42 -> iam_menu-42 | G27: hzero-admin.gateway-rate-limit-dimension-site-level.delete
... E45: iam_menu_permission-45 | F45: =菜单SAAS版!$E$42 -> iam_menu-42 | G45: hzero-admin.gateway-rate-limit-site-level.update
E46: iam_menu_permission-46 | F46: =菜单SAAS版!$E$11 -> iam_menu-11 | G46: HADM.DATASOURCE
E47: iam_menu_permission-47 | F47: =菜单SAAS版!$E$11 -> iam_menu-11 | G47: HADM.DATASOURCE_GROUP
E48: iam_menu_permission-48 | F48: =菜单SAAS版!$E$11 -> iam_menu-11 | G48: HADM.PROXY_LINE_TABLE
E49: iam_menu_permission-49 | F49: =菜单SAAS版!$E$11 -> iam_menu-11 | G49: HADM.SERVICE
E50: iam_menu_permission-50 | F50: =菜单SAAS版!$E$11 -> iam_menu-11 | G50: HADM.SERVICE_DATASOURCE
E51: iam_menu_permission-51 | F51: =菜单SAAS版!$E$11 -> iam_menu-11 | G51: hzero-admin.access-statistics-site.queryApiInvokeCount
E52: iam_menu_permission-52 | F52: =菜单SAAS版!$E$11 -> iam_menu-11 | G52: hzero-admin.service-instance-site.list
E53: iam_menu_permission-53 | F53: =菜单SAAS版!$E$11 -> iam_menu-11 | G53: hzero-admin.service-instance-site.query
E54: iam_menu_permission-54 | F54: =菜单SAAS版!$E$11 -> iam_menu-11 | G54: hzero-admin.sp-logic-datasource-group-site.detail
E55: iam_menu_permission-55 | F55: =菜单SAAS版!$E$11 -> iam_menu-11 | G55: hzero-admin.sp-logic-datasource-group-site.list
E56: iam_menu_permission-56 | F56: =菜单SAAS版!$E$11 -> iam_menu-11 | G56: hzero-admin.sp-logic-datasource-group-site.remove
E57: iam_menu_permission-57 | F57: =菜单SAAS版!$E$11 -> iam_menu-11 | G57: hzero-admin.sp-logic-datasource-group-site.save
... E76: iam_menu_permission-76 | F76: =菜单SAAS版!$E$11 -> iam_menu-11 | G76: hzero-iam.doc-type-site-level.queryDocTypeByOptions
E77: iam_menu_permission-77 | F77: =菜单SAAS版!$E$46 -> iam_menu-46 | G77: hzero-admin.node-rule-site.create
E78: iam_menu_permission-78 | F78: =菜单SAAS版!$E$46 -> iam_menu-46 | G78: hzero-admin.node-rule-site.detail
E79: iam_menu_permission-79 | F79: =菜单SAAS版!$E$46 -> iam_menu-46 | G79: hzero-admin.node-rule-site.disable
...

Sheet 角色权限
A1: 日期 | B1: 作者 | C1: 说明 | D1: 表
E4: *自动生成 | F4: #唯一性检查 | G4: 公式=外键引用
A7: 2020-07-09 | B7: hzero | C7: 角色 | D7: iam_role | E7: *id | F7: name:zh_CN | G7: name:en_US | H7: #code | I7: description | J7: fd_level | K7: #h_tenant_id | L7: h_inherit_role_id | M7: #h_parent_role_id | N7: #h_parent_role_assign_level | O7: h_parent_role_assign_level_val | P7: is_enabled | Q7: is_modified | R7: is_enable_forbidden | S7: is_built_in | T7: is_assignable | U7: h_level_path | V7: h_inherit_level_path | W7: #created_by_tenant_id | X7: tpl_role_name:zh_CN | Y7: tpl_role_name:en_US
E8: iam_role-8 | F8: 平台管理员 | G8: Site Administrator | H8: role/site/default/administrator | I8: abcf | J8: site | K8: 0 | L8: 0 | M8: 0 | N8: organization | O8: 0 | P8: 1 | Q8: 0 | R8: 1 | S8: 1 | T8: 0 | U8: role/site/default/administrator | V8: role/site/default/administrator | W8: 0
E9: iam_role-9 | F9: 租户管理员 | G9: Organization Administrator | H9: role/organization/default/administrator | I9: abce | J9: organization | K9: 0 | L9: 0 | M9: 0 | N9: organization | O9: 0 | P9: 1 | Q9: 0 | R9: 1 | S9: 1 | T9: 0 | U9: role/organization/default/administrator | V9: role/organization/default/administrator | W9: 0
E10: iam_role-10 | F10: 租户管理员模板 | G10: Tenant admin template | H10: role/organization/default/template/administrator | J10: organization | K10: 0 | L10: 0 | M10: =角色权限!$E$9 -> iam_role-9 | N10: organization | O10: 0 | P10: 1 | Q10: 0 | R10: 1 | S10: 1 | T10: 0 | U10: role/organization/default/administrator|HZERO.T.role/organization/default/template/administrator | V10: HZERO.T.role/organization/default/template/administrator | W10: 0 | X10: 租户管理员 | Y10: Tenant Admin
A12: 2020-07-09 | B12: hzero | C12: 角色权限 | D12: iam_role_permission | E12: *id | F12: #role_id | G12: #permission_id | H12: h_create_flag | I12: h_inherit_flag | J12: #type
E13: iam_role_permission-13 | F13: =角色权限!$E$8 -> iam_role-8 | G13: =菜单SAAS版!$E$31 -> iam_menu-31 | H13: Y | I13: N | J13: PS
E14: iam_role_permission-14 | F14: =角色权限!$E$8 -> iam_role-8 | G14: =菜单SAAS版!$E$32 -> iam_menu-32 | H14: Y | I14: N | J14: PS
E15: iam_role_permission-15 | F15: =角色权限!$E$9 -> iam_role-9 | G15: =菜单SAAS版!$E$33 -> iam_menu-33 | H15: Y | I15: N | J15: PS
E16: iam_role_permission-16 | F16: =角色权限!$E$10 -> iam_role-10 | G16: =菜单SAAS版!$E$33 -> iam_menu-33 | H16: Y | I16: N | J16: PS
E17: iam_role_permission-17 | F17: =角色权限!$E$8 -> iam_role-8 | G17: =菜单SAAS版!$E$33 -> iam_menu-33 | H17: Y | I17: N | J17: PS
E18: iam_role_permission-18 | F18: =角色权限!$E$8 -> iam_role-8 | G18: =菜单SAAS版!$E$34 -> iam_menu-34 | H18: Y | I18: N | J18: PS
E19: iam_role_permission-19 | F19: =角色权限!$E$8 -> iam_role-8 | G19: =菜单SAAS版!$E$35 -> iam_menu-35 | H19: Y | I19: N | J19: PS
E20: iam_role_permission-20 | F20: =角色权限!$E$8 -> iam_role-8 | G20: =菜单SAAS版!$E$36 -> iam_menu-36 | H20: Y | I20: N | J20: PS
E21: iam_role_permission-21 | F21: =角色权限!$E$8 -> iam_role-8 | G21: =菜单SAAS版!$E$38 -> iam_menu-38 | H21: Y | I21: N | J21: PS
E22: iam_role_permission-22 | F22: =角色权限!$E$8 -> iam_role-8 | G22: =菜单SAAS版!$E$39 -> iam_menu-39 | H22: Y | I22: N | J22: PS
E23: iam_role_permission-23 | F23: =角色权限!$E$8 -> iam_role-8 | G23: =菜单SAAS版!$E$40 -> iam_menu-40 | H23: Y | I23: N | J23: PS
E24: iam_role_permission-24 | F24: =角色权限!$E$8 -> iam_role-8 | G24: =菜单SAAS版!$E$41 -> iam_menu-41 | H24: Y | I24: N | J24: PS
E25: iam_role_permission-25 | F25: =角色权限!$E$8 -> iam_role-8 | G25: =菜单SAAS版!$E$42 -> iam_menu-42 | H25: Y | I25: N | J25: PS
E26: iam_role_permission-26 | F26: =角色权限!$E$8 -> iam_role-8 | G26: =菜单SAAS版!$E$43 -> iam_menu-43 | H26: Y | I26: N | J26: PS
E27: iam_role_permission-27 | F27: =角色权限!$E$8 -> iam_role-8 | G27: =菜单SAAS版!$E$44 -> iam_menu-44 | H27: Y | I27: N | J27: PS
E28: iam_role_permission-28 | F28: =角色权限!$E$8 -> iam_role-8 | G28: =菜单SAAS版!$E$11 -> iam_menu-11 | H28: Y | I28: N | J28: PS
E29: iam_role_permission-29 | F29: =角色权限!$E$8 -> iam_role-8 | G29: =菜单SAAS版!$E$46 -> iam_menu-46 | H29: Y | I29: N | J29: PS
E30: iam_role_permission-30 | F30: =角色权限!$E$8 -> iam_role-8 | G30: =菜单SAAS版!$E$13 -> iam_menu-13 | H30: Y | I30: N | J30: PS
E31: iam_role_permission-31 | F31: =角色权限!$E$8 -> iam_role-8 | G31: =菜单SAAS版!$E$15 -> iam_menu-15 | H31: Y | I31: N | J31: PS
E32: iam_role_permission-32 | F32: =角色权限!$E$8 -> iam_role-8 | G32: =菜单SAAS版!$E$17 -> iam_menu-17 | H32: Y | I32: N | J32: PS
E33: iam_role_permission-33 | F33: =角色权限!$E$8 -> iam_role-8 | G33: =菜单SAAS版!$E$19 -> iam_menu-19 | H33: Y | I33: N | J33: PS
E34: iam_role_permission-34 | F34: =角色权限!$E$9 -> iam_role-9 | G34: =菜单SAAS版!$E$20 -> iam_menu-20 | H34: Y | I34: N | J34: PS
E35: iam_role_permission-35 | F35: =角色权限!$E$8 -> iam_role-8 | G35: =菜单SAAS版!$E$20 -> iam_menu-20 | H35: Y | I35: N | J35: PS
E36: iam_role_permission-36 | F36: =角色权限!$E$8 -> iam_role-8 | G36: =菜单SAAS版!$E$21 -> iam_menu-21 | H36: Y | I36: N | J36: PS
E37: iam_role_permission-37 | F37: =角色权限!$E$8 -> iam_role-8 | G37: =菜单SAAS版!$E$22 -> iam_menu-22 | H37: Y | I37: N | J37: PS
E38: iam_role_permission-38 | F38: =角色权限!$E$8 -> iam_role-8 | G38: =菜单SAAS版!$E$24 -> iam_menu-24 | H38: Y | I38: N | J38: PS
E39: iam_role_permission-39 | F39: =角色权限!$E$9 -> iam_role-9 | G39: =菜单SAAS版!$E$25 -> iam_menu-25 | H39: Y | I39: N | J39: PS
E40: iam_role_permission-40 | F40: =角色权限!$E$8 -> iam_role-8 | G40: =菜单SAAS版!$E$25 -> iam_menu-25 | H40: Y | I40: N | J40: PS
E41: iam_role_permission-41 | F41: =角色权限!$E$8 -> iam_role-8 | G41: =菜单SAAS版!$E$26 -> iam_menu-26 | H41: Y | I41: N | J41: PS
E42: iam_role_permission-42 | F42: =角色权限!$E$8 -> iam_role-8 | G42: =菜单SAAS版!$E$27 -> iam_menu-27 | H42: Y | I42: N | J42: PS
E43: iam_role_permission-43 | F43: =角色权限!$E$8 -> iam_role-8 | G43: =菜单SAAS版!$E$48 -> iam_menu-48 | H43: Y | I43: N | J43: PS
E44: iam_role_permission-44 | F44: =角色权限!$E$8 -> iam_role-8 | G44: =菜单SAAS版!$E$49 -> iam_menu-49 | H44: Y | I44: N | J44: PS
E45: iam_role_permission-45 | F45: =角色权限!$E$8 -> iam_role-8 | G45: =菜单SAAS版!$E$50 -> iam_menu-50 | H45: Y | I45: N | J45: PS
...

Sheet 菜单标签数据
A1: 日期 | B1: 作者 | C1: 说明 | D1: 表
E4: *自动生成 | F4: #唯一性检查 | G4: 公式=外键引用
A7: 2020-07-09 | B7: hzero | C7: 标签表 | D7: iam_label | E7: *id | F7: #name | G7: #type | H7: enabled_flag | I7: fd_level | J7: description:zh_CN | K7: description:en_US | L7: tag | M7: inherit_flag | N7: preset_flag | O7: visible_flag
E8: iam_label-8 | F8: HZERO_MENU | G8: MENU | H8: 1 | I8: SITE | J8: HZERO菜单标签 | K8: HZERO菜单标签 | M8: 1 | N8: 1 | O8: 1
E9: iam_label-9 | F9: USER_MENU | G9: MENU | H9: 1 | I9: SITE | M9: 0 | N9: 0 | O9: 1
A11: 2020-07-09 | B11: hzero | C11: 标签关系表 | D11: hiam_label_rel | E11: *label_rel_id | F11: #data_type | G11: #data_id | H11: #label_id | I11: assign_type
E12: * | F12: MENU | G12: =菜单SAAS版!$E$8 -> iam_menu-8 | H12: =菜单标签数据!$E$8 -> iam_label-8 | I12: A
E13: * | F13: MENU | G13: =菜单SAAS版!$E$18 -> iam_menu-18 | H13: =菜单标签数据!$E$8 -> iam_label-8 | I13: A
E14: * | F14: MENU | G14: =菜单SAAS版!$E$23 -> iam_menu-23 | H14: =菜单标签数据!$E$8 -> iam_label-8 | I14: A
E15: * | F15: MENU | G15: =菜单SAAS版!$E$9 -> iam_menu-9 | H15: =菜单标签数据!$E$8 -> iam_label-8 | I15: A
E16: * | F16: MENU | G16: =菜单SAAS版!$E$29 -> iam_menu-29 | H16: =菜单标签数据!$E$8 -> iam_label-8 | I16: A
E17: * | F17: MENU | G17: =菜单SAAS版!$E$31 -> iam_menu-31 | H17: =菜单标签数据!$E$8 -> iam_label-8 | I17: A
E18: * | F18: MENU | G18: =菜单SAAS版!$E$32 -> iam_menu-32 | H18: =菜单标签数据!$E$8 -> iam_label-8 | I18: A
E19: * | F19: MENU | G19: =菜单SAAS版!$E$33 -> iam_menu-33 | H19: =菜单标签数据!$E$8 -> iam_label-8 | I19: A
E20: * | F20: MENU | G20: =菜单SAAS版!$E$34 -> iam_menu-34 | H20: =菜单标签数据!$E$8 -> iam_label-8 | I20: A
E21: * | F21: MENU | G21: =菜单SAAS版!$E$35 -> iam_menu-35 | H21: =菜单标签数据!$E$8 -> iam_label-8 | I21: A
E22: * | F22: MENU | G22: =菜单SAAS版!$E$36 -> iam_menu-36 | H22: =菜单标签数据!$E$8 -> iam_label-8 | I22: A
E23: * | F23: MENU | G23: =菜单SAAS版!$E$38 -> iam_menu-38 | H23: =菜单标签数据!$E$8 -> iam_label-8 | I23: A
E24: * | F24: MENU | G24: =菜单SAAS版!$E$39 -> iam_menu-39 | H24: =菜单标签数据!$E$8 -> iam_label-8 | I24: A
E25: * | F25: MENU | G25: =菜单SAAS版!$E$40 -> iam_menu-40 | H25: =菜单标签数据!$E$8 -> iam_label-8 | I25: A
E26: * | F26: MENU | G26: =菜单SAAS版!$E$41 -> iam_menu-41 | H26: =菜单标签数据!$E$8 -> iam_label-8 | I26: A
E27: * | F27: MENU | G27: =菜单SAAS版!$E$42 -> iam_menu-42 | H27: =菜单标签数据!$E$8 -> iam_label-8 | I27: A
E28: * | F28: MENU | G28: =菜单SAAS版!$E$43 -> iam_menu-43 | H28: =菜单标签数据!$E$8 -> iam_label-8 | I28: A
E29: * | F29: MENU | G29: =菜单SAAS版!$E$44 -> iam_menu-44 | H29: =菜单标签数据!$E$8 -> iam_label-8 | I29: A
E30: * | F30: MENU | G30: =菜单SAAS版!$E$11 -> iam_menu-11 | H30: =菜单标签数据!$E$8 -> iam_label-8 | I30: A
E31: * | F31: MENU | G31: =菜单SAAS版!$E$46 -> iam_menu-46 | H31: =菜单标签数据!$E$8 -> iam_label-8 | I31: A
E32: * | F32: MENU | G32: =菜单SAAS版!$E$19 -> iam_menu-19 | H32: =菜单标签数据!$E$8 -> iam_label-8 | I32: A
E33: * | F33: MENU | G33: =菜单SAAS版!$E$20 -> iam_menu-20 | H33: =菜单标签数据!$E$8 -> iam_label-8 | I33: A
E34: * | F34: MENU | G34: =菜单SAAS版!$E$21 -> iam_menu-21 | H34: =菜单标签数据!$E$8 -> iam_label-8 | I34: A
E35: * | F35: MENU | G35: =菜单SAAS版!$E$22 -> iam_menu-22 | H35: =菜单标签数据!$E$8 -> iam_label-8 | I35: A
E36: * | F36: MENU | G36: =菜单SAAS版!$E$24 -> iam_menu-24 | H36: =菜单标签数据!$E$8 -> iam_label-8 | I36: A
E37: * | F37: MENU | G37: =菜单SAAS版!$E$25 -> iam_menu-25 | H37: =菜单标签数据!$E$8 -> iam_label-8 | I37: A
E38: * | F38: MENU | G38: =菜单SAAS版!$E$26 -> iam_menu-26 | H38: =菜单标签数据!$E$8 -> iam_label-8 | I38: A
E39: * | F39: MENU | G39: =菜单SAAS版!$E$27 -> iam_menu-27 | H39: =菜单标签数据!$E$8 -> iam_label-8 | I39: A
E40: * | F40: MENU | G40: =菜单SAAS版!$E$10 -> iam_menu-10 | H40: =菜单标签数据!$E$8 -> iam_label-8 | I40: A
E41: * | F41: MENU | G41: =菜单SAAS版!$E$12 -> iam_menu-12 | H41: =菜单标签数据!$E$8 -> iam_label-8 | I41: A
E42: * | F42: MENU | G42: =菜单SAAS版!$E$14 -> iam_menu-14 | H42: =菜单标签数据!$E$8 -> iam_label-8 | I42: A
E43: * | F43: MENU | G43: =菜单SAAS版!$E$16 -> iam_menu-16 | H43: =菜单标签数据!$E$8 -> iam_label-8 | I43: A
E44: * | F44: MENU | G44: =菜单SAAS版!$E$13 -> iam_menu-13 | H44: =菜单标签数据!$E$8 -> iam_label-8 | I44: A
E45: * | F45: MENU | G45: =菜单SAAS版!$E$15 -> iam_menu-15 | H45: =菜单标签数据!$E$8 -> iam_label-8 | I45: A
...
